Workbook

Sheet Strona tytułowa
A1: Finanse i rachunkowość Analiza finansowa spółki Atende SA Lata analizy: 2022 - 2024 Oliwia Samborska, Zofia Padoł, Magdalena Kluszczyńska

Sheet Wprowadzenie
A1: Przedmiotem naszej analizy jest Grupa Kapitałowa Atende S.A., jeden z czołowych dostawców usług IT w Polsce, notowany na Giełdzie Papierów Wartościowych w Warszawie. Spółka funkcjonuje w sektorze nowoczesnych technologii, co w istotny sposób determinuje strukturę jej sprawozdania finansowego oraz wartości poszczególnych wskaźników. Główne obszary działalności Grupy Atende obejmują: - Integrację systemów IT: budowa złożonej infrastruktury informatycznej i centrów danych. - Cyberbezpieczeństwo: dostarczanie zaawansowanych rozwiązań ochrony danych. - Usługi w chmurze (Cloud): oferowanie mocy obliczeniowej w modelu abonamentowym. - Energetykę cyfrową: tworzenie innowacyjnego oprogramowania dla inteligentnych sieci energetycznych. Z punktu widzenia analizy finansowej, branża IT charakteryzuje się wysoką dynamiką zmian, dużą zależnością od kapitału ludzkiego oraz modelem biznesowym typu asset-light (przewaga aktywów obrotowych nad trwałymi). W analizowanym okresie Grupa koncentrowała się na transformacji w kierunku sprzedaży usług własnych o wyższej marży, co przy jednoczesnych wysokich kosztach operacyjnych i inwestycjach w innowacje, miało kluczowy wpływ na prezentowane wyniki finansowe, w tym na relację między zyskiem księgowym a generowanymi przepływami pieniężnymi.

Sheet WybraneElementy
A1: Wybrane elementy bilansu
B2: stan na 31.12.2024 | C2: stan na 31.12.2023 | D2: stan na 31.12.2022 | F2: Przeciętny stan aktywów ogółem: | G2: =SUM(B8:D8)/3 -> 191400
A3: Aktywa trwałe | B3: 56391 | C3: 56561 | D3: 50372 | F3: Średni stan zapasów: | G3: =SUM(B7:D7)/3 -> 5989.6667
A4: Aktywa obrotowe | B4: 175331 | C4: 141886 | D4: 93659 | F4: Średni stan należności: | G4: =SUM(B6:D6)/3 -> 51568.667
A5: Pozostałe aktywa krótkoterminowe(jako rozliczenia m.ok.) | B5: 19703 | C5: 16640 | D5: 11460
A6: Należności z tytułu dostaw i usług (do rotacji) | B6: 52788 | C6: 54008 | D6: 47910
A7: Zapasy | B7: 2645 | C7: 4099 | D7: 11225
A8: Aktywa razem | B8: 231722 | C8: 198447 | D8: 144031
A10: Kapitał własny | B10: 86052 | C10: 83224 | D10: 70018
A11: Zob. dł. | B11: 22533 | C11: 21514 | D11: 8255
A12: Zob. kr. | B12: 123137 | C12: 93709 | D12: 65758
A13: Zobowiązania z tytułu dostaw i usług | B13: 76121 | C13: 41993 | D13: 32874
A14: Pasywa razem | B14: 231722 | C14: 198447 | D14: 144031
A17: Rachunek zysków i strat
B18: stan na 31.12.2024 | C18: stan na 31.12.2023 | D18: stan na 31.12.2022
A19: Przychody netto ze sprzedaży | B19: 307209 | C19: 291027 | D19: 198413
A20: Koszt własny sprzedaży | B20: 255102 | C20: 234233 | D20: 160148
A21: Zysk brutto na sprzedaży | B21: 52107 | C21: 56794 | D21: 38265
A22: Zysk/(strata) na działalności operacyjnej | B22: 11882 | C22: 17319 | D22: 1340
A23: Zysk/(strata) przed opodatkowaniem | B23: 13008 | C23: 16550 | D23: 1096
A24: Zysk/(strata) netto | B24: 10319 | C24: 13269 | D24: 715
A27: Cash flow
B28: stan na 31.12.2024 | C28: stan na 31.12.2023 | D28: stan na 31.12.2022
A29: DZIAŁALNOŚĆ OPERACYJNA
A30: Zysk/ (strata) przed opodatkowaniem | B30: 13008 | C30: 16550 | D30: 1096
A31: Przepływy z działalności operacyjnej | B31: 56797 | C31: 39842 | D31: 12062
A32: Przepływy pieniężne netto z działalności operacyjnej | B32: 54644 | C32: 37177 | D32: 12062
A33: DZIAŁALNOŚĆ INWESTYCYJNA
A34: Wpływy: | B34: 1900 | C34: 2330 | D34: 300
A35: Wydatki: | B35: 24893 | C35: 24115 | D35: 3221
A36: Przepływy pieniężne netto z działalności inwestycyjnej | B36: -22993 | C36: -21785 | D36: -2921
A37: DZIAŁALNOŚĆ FINANSOWA
A38: Wpływy: | B38: 9490 | C38: 8036 | D38: 9651
A39: Wydatki: | B39: 18992 | C39: 6780 | D39: 12622
A40: Spłaty kredytów i pożyczek | B40: 9889 | C40: 2851 | D40: 8759
A41: Dywidendy | B41: 5088 | C41: - | D41: -
A42: Odsetki | B42: 1051 | C42: 314 | D42: 361
A43: Przepływy pieniężne netto z działalności finansowej | B43: -9502 | C43: 1256 | D43: -2970
A44: PRZEPŁYWY PIENIĘŻNE NETTO RAZEM | B44: 22149 | C44: 16648 | D44: 6171
A45: Środki pieniężne na początek okresu | B45: 29632 | C45: 12984 | D45: 6813
...

Sheet Cash Flow
A1: Kolumna3 | B1: Kolumna2 | C1: Kolumna1 | D1: Kolumna12
B2: 2024 r. | C2: 2023 r. | D2: 2022 r.
A3: DZIAŁALNOŚĆ OPERACYJNA
A4: Zysk przed opodatkowaniem | B4: 13 008 | C4: 16 550 | D4: 1 096
A5: Korekty razem: | B5: 43 789 | C5: 23 292 | D5: 10 966
A6: Amortyzacja | B6: 6 445 | C6: 6 836 | D6: 6 676
A7: Zyski (straty) z tytułu różnic kursowych | B7: (21) | C7: (106) | D7: 76
A8: Odsetki i udziały w zyskach (dywidendy) | B8: (1 762) | C8: (676) | D8: 263
A9: Zyski z działalności inwestycyjnej | B9: 19 | C9: 15 | D9: 9
A10: Inne korekty | B10: 101 | C10: (535) | D10: (1 425)
A11: Zmiana kapitału pracującego, w tym: | B11: 42 823 | C11: 28 806 | D11: (8 142)
A12: Zapasy | B12: 1 303 | C12: 6 758 | D12: (6 942)
A13: Należności | B13: 13 514 | C13: (12 119) | D13: 13 207
A14: Zobowiązania i rezerwy | B14: 28 006 | C14: 34 167 | D14: (14 407)
A15: Zmiana stanu pozostałych aktywów | B15: (3 816) | C15: (11 048) | D15: 13 509
... A18: Przepływy pieniężne netto z działalności operacyjnej | B18: 54 644 | C18: 37 177 | D18: 12 062
A19: DZIAŁALNOŚĆ INWESTYCYJNA
A20: Wpływy: | B20: 1 900 | C20: 2 330 | D20: 300
A21: Zbycie wartości niematerialnych oraz rzeczowych aktywów trwałych | B21: 17 | C21: 158 | D21: 46
A22: Środki pieniężne przejęte w ramach połączenia z jednostką zależną | B22: 193 | C22: - | D22: 12
A23: Dotacje | B23: 118 | C23: 364 | D23: -
A24: Spłata udzielonych pożyczek | B24: 1 572 | C24: 1 808 | D24: 242
A25: Wydatki: | B25: 24 893 | C25: 24 115 | D25: 3 221
A26: Nabycie wartości niematerialnych oraz rzeczowych aktywów trwałych | B26: 1 793 | C26: 3 037 | D26: 3 021
A27: Wydatki na aktywa finansowe | B27: 23 100 | C27: 19 878 | D27: 200
A28: Nabycie udziałów w jednostce stowarzyszonej | B28: - | C28: 1 200 | D28: -
A29: Przepływy pieniężne netto z działalności inwestycyjnej | B29: (22 993) | C29: (21 785) | D29: (2 921)
A30: DZIAŁALNOŚĆ FINANSOWA
A31: Wpływy: | B31: 9 490 | C31: 8 036 | D31: 9 651
A32: Kredyty i pożyczki | B32: 9 490 | C32: 8 036 | D32: 9 651
A33: Wydatki: | B33: 18 992 | C33: 6 780 | D33: 12 622
A34: Dywidendy | B34: 5088 | C34: - | D34: -
A35: Spłaty kredytów i pożyczek | B35: 9 889 | C35: 2 851 | D35: 8759
A36: Płatności zobowiązań z tytułu umów leasingu | B36: 2 703 | C36: 3 408 | D36: 3297
A37: Odsetki | B37: 1051 | C37: 314 | D37: 361
A38: Inne wydatki finansowe | B38: 261 | C38: 207 | D38: 204
A39: Przepływy pieniężne netto z działalności finansowej | B39: -9502 | C39: 1 256 | D39: -2970
A40: PRZEPŁYWY PIENIĘŻNE NETTO RAZEM | B40: 22149 | C40: 16648 | D40: 6171
A41: Bilansowa zmiana stanu środków pieniężnych, w tym: | B41: 22 149 | C41: 16 648 | D41: 6171
A42: - zmiana stanu środków pieniężnych z tytułu różnic kursowych | B42: - | C42: - | D42: -
...

Sheet Bilans
A1: AKTYWA | B1: Nota | C1: stan na 31.12.2024 | D1: stan na 31.12.2023 | E1: stan na 31.12.2022
A2: Aktywa trwałe | C2: 56391 | D2: 56561 | E2: 50 372
A3: Rzeczowe aktywa trwałe | B3: 11 | C3: 14 284 | D3: 14462 | E3: =RZiS!C8 * 100 / ((Bilans!D20 + Bilans!C20)/2) -> 5.5243404
A4: Wartości niematerialne | B4: 12 | C4: 5 359 | D4: 6176 | E4: 5 494
A5: Aktywa z tytułu prawa do użytkowania | B5: 28 | C5: 7 878 | D5: 5356 | E5: 4 129
A6: Inwestycje w jednostki podporządkowane | B6: 14 | C6: 15 945 | D6: 17946 | E6: 16 946
A7: Pozostałe długoterminowe aktywa finansowe | B7: 16 | C7: - | D7: 200 | E7: -
A8: Aktywa wyceniane w wartości godziwej przez pozostałe całkowite dochody | C8: 80 | D8: 80 | E8: 80
A9: Aktywa z tytułu odroczonego podatku dochodowego | B9: 7 | C9: 1049 | D9: 2282 | E9: 1 264
A10: Aktywa z tytułu umów z klientami | B10: 1 | C10: 1 206 | D10: 237 | E10: 2 619
A11: Pozostałe aktywa trwałe | B11: 20 | C11: 10 590 | D11: 9822 | E11: 3 945
A12: Aktywa obrotowe | C12: 175 331 | D12: 141886 | E12: 93 659
A13: Zapasy | B13: 17 | C13: 2 645 | D13: 4099 | E13: 11225
A14: Aktywa z tytułu umów z klientami | B14: 1 | D14: 15593 | E14: 7 554
A15: Należności z tytułu dostaw i usług | B15: 18 | C15: 52 788 | D15: 54008 | E15: 47 910
A16: Pozostałe należności | B16: 19 | C16: 992 | D16: 773 | E16: 418
A17: Pozostałe aktywa finansowe | B17: 16 | C17: 45 302 | D17: 21141 | E17: 2 108
A18: Pozostałe aktywa krótkoterminowe | B18: 20 | C18: 19 703 | D18: 16640 | E18: 11 460
A19: Środki pieniężne i ich ekwiwalenty | B19: 21 | C19: 51 781 | D19: 29632 | E19: 12 984
A20: AKTYWA RAZEM | C20: 231 722 | D20: 198447 | E20: 144 031
A21: PASYWA | B21: Nota | C21: stan na 31.12.2024 | D21: 0 | E21: stan na 31.12.2022
A22: Kapitał własny | C22: 86 052 | D22: 83224 | E22: 70 018
A23: Kapitał zakładowy | B23: 22 | C23: 7 269 | D23: 7269 | E23: 7 269
A24: Kapitał zapasowy z emisji akcji powyżej wartości nominalnej | B24: 23 | C24: 14 753 | D24: 14753 | E24: 14 753
A25: Zyski zatrzymane | C25: 64 030 | D25: 61202 | E25: 47 996
A26: Zobowiązania długoterminowe | C26: 22 533 | D26: 21514 | E26: 8 255
A27: Kredyty i pożyczki | B27: 24 | C27: 3 088 | D27: 3063 | E27: 558
A28: Zobowiązania z tytułu leasingu | B28: 28 | C28: 5 280 | D28: 2860 | E28: 12
A29: Zobowiązania z tytułu umów z klientami | B29: 1 | C29: 13 093 | D29: 14487 | E29: 1 733
A30: Pozostałe zobowiązania długoterminowe | C30: 13 | E30: 5 114
A31: Rozliczenia międzyokresowe przychodów | B31: 29 | C31: 218 | D31: 291 | E31: -
A32: Rezerwa na świadczenia emerytalne i podobne | B32: 30 | C32: 841 | D32: 813 | E32: 838
A33: Zobowiązania krótkoterminowe | C33: 123 137 | D33: 93709 | E33: 65 758
A34: Kredyty i pożyczki | B34: 24 | C34: 5 536 | D34: 5443 | E34: 3 285
A35: Pozostałe zobowiązania finansowe | C35: - | D35: 205 | E35: 523
A36: Zobowiązania z tytułu leasingu | B36: 28 | C36: 2 598 | D36: 2249 | E36: 2 577
A37: Zobowiązania z tytułu umów z klientami | B37: 1 | C37: 18 856 | D37: 23086 | E37: 11 925
A38: Zobowiązania z tytułu dostaw i usług | B38: 26 | C38: 76 121 | D38: 41993 | E38: 32 874
A39: Zobowiązania z tytułu bieżącego podatku dochodowego | C39: 942 | D39: 1633 | E39: -
A40: Pozostałe zobowiązania krótkoterminowe | B40: 26 | C40: 18 865 | D40: 18901 | E40: 14 474
...

Sheet RZiS
A1: Kolumna1 | B1: Nota | C1: 2024 r. | D1: 2023 r. | E1: 2022 r.
A2: Przychody ze sprzedaży | B2: 2 | C2: 307209 | D2: 291027 | E2: 198413
A3: Koszt własny sprzedaży | B3: 3 | C3: 255102 | D3: 234233 | E3: 160148
A4: Zysk brutto na sprzedaży | C4: 52107 | D4: 56794 | E4: 38265
A5: Pozostałe przychody operacyjne | B5: 5 | C5: 605 | D5: 591 | E5: 139
A6: Koszty ogólnego zarządu | B6: 3 | C6: 40619 | D6: 39 542 | E6: 36 890
A7: Pozostałe koszty operacyjne | B7: 5 | C7: 211 | D7: 524 | E7: 174
A8: Zysk na działalności operacyjnej | C8: 11882 | D8: 17319 | E8: 1340
A9: Przychody finansowe | B9: 6 | C9: 3 297 | D9: 1 238 | E9: 927
A10: Koszty finansowe | B10: 6 | C10: 2 171 | D10: 2 007 | E10: 1 171
A11: Zysk przed opodatkowaniem | C11: 13008 | E11: 1096
A12: Podatek dochodowy | B12: 7 | C12: 2 689 | D12: 3 281 | E12: 381
A13: Zysk netto | C13: 10319 | D13: 13269 | E13: 715
A15: Składniki innych dochodów całkowitych:
A16: - które zostaną przekwalifikowane na zyski lub straty po spełnieniu określonych warunków | C16: - | D16: - | E16: -
A17: - które nie zostaną przekwalifikowane na zyski lub straty w kolejnych okresach | C17: - | D17: - | E17: -
A18: Suma dochodów całkowitych | C18: 10 319 | D18: 13 269 | E18: 715
A20: Zysk netto na jedną akcję (w zł)
A21: Podstawowy za okres obrotowy | B21: 8 | C21: 0,28 | D21: 0,37 | E21: 0,02
A22: Rozwodniony za okres obrotowy | C22: 0,28 | D22: 0,37 | E22: 0,02

Sheet Analiza wstępna
A1: 1. Analiza Pozioma
A2: Wybrane elementy bilansu | E2: Zmiana bezwzględna 2024/2023 | F2: Zmiana bezwzględna 2023/2022 | G2: Tempo zmian 2024/2023 | H2: Tempo zmian 2023/2022 | I2: Wskaźnik dynamiki 2024/2023 | J2: Wskaźnik dynamiki 2023/2022 | L2: Wnioski: -W badanym okresie (2022–2024) spółka odnotowała bardzo silny wzrost przychodów ze sprzedaży -o 46,68% w 2023 roku i o kolejne 5,56% w 2024 roku. -Tempo wzrostu kosztów własnych sprzedaży w 2024 roku (8,91%) było wyższe niż tempo wzrostu przychodów (5,56%), co skutkowało spadkiem zysku netto o 22,23% r/r. -Suma bilansowa wzrosła w ciągu dwóch lat o ponad 60% (z 144 mln zł do 231 mln zł), co napędzane było głównie przez dynamiczny przyrost aktywów obrotowych. -Najbardziej dynamicznie rosnącą pozycją w pasywach są zobowiązania krótkoterminowe, które wzrosły o 31,40% w ostatnim roku (z 93,7 mln zł do 123,1 mln zł). Tak szybki przyrost długu bieżącego, przy jednoczesnym wzroście zapasów i należności, sugeruje, że spółka w dużym stopniu finansuje swoją ekspansję operacyjną darmowym kredytem kupieckim lub krótkoterminowymi liniami kredytowymi.
B3: stan na 31.12.2024 | C3: stan na 31.12.2023 | D3: stan na 31.12.2022
A4: Aktywa trwałe | B4: 56391 | C4: 56561 | D4: 50372 | E4: =B4-C4 -> -170 | F4: =C4-D4 -> 6189 | G4: =E4/C4 -> -0.0030056046 | H4: =F4/D4 -> 0.12286588 | I4: =B4/C4 -> 0.9969944 | J4: =C4/D4 -> 1.1228659
A5: Aktywa obrotowe | B5: 175331 | C5: 141886 | D5: 93659 | E5: =B5-C5 -> 33445 | F5: =C5-D5 -> 48227 | G5: =E5/C5 -> 0.23571741 | H5: =F5/D5 -> 0.51492115 | I5: =B5/C5 -> 1.2357174 | J5: =C5/D5 -> 1.5149212
A6: Aktywa razem | B6: 231722 | C6: 198447 | D6: 144031 | E6: =B6-C6 -> 33275 | F6: =C6-D6 -> 54416 | G6: =E6/C6 -> 0.16767701 | H6: =F6/D6 -> 0.37780756 | I6: =B6/C6 -> 1.167677 | J6: =C6/D6 -> 1.3778076
A7: Kapitał własny | B7: 86052 | C7: 83224 | D7: 70018 | E7: =B7-C7 -> 2828 | F7: =C7-D7 -> 13206 | G7: =E7/C7 -> 0.033980583 | H7: =F7/D7 -> 0.18860864 | I7: =B7/C7 -> 1.0339806 | J7: =C7/D7 -> 1.1886086
A8: Zob. dł. | B8: 22533 | C8: 21514 | D8: 8255 | E8: =B8-C8 -> 1019 | F8: =C8-D8 -> 13259 | G8: =E8/C8 -> 0.047364507 | H8: =F8/D8 -> 1.6061781 | I8: =B8/C8 -> 1.0473645 | J8: =C8/D8 -> 2.6061781
A9: Zob. kr. | B9: 123137 | C9: 93709 | D9: 65758 | E9: =B9-C9 -> 29428 | F9: =C9-D9 -> 27951 | G9: =E9/C9 -> 0.31403601 | H9: =F9/D9 -> 0.42505855 | I9: =B9/C9 -> 1.314036 | J9: =C9/D9 -> 1.4250585
A10: Pasywa razem | B10: 231722 | C10: 198447 | D10: 144031 | E10: =B10-C10 -> 33275 | F10: =C10-D10 -> 54416 | G10: =E10/C10 -> 0.16767701 | H10: =F10/D10 -> 0.37780756 | I10: =B10/C10 -> 1.167677 | J10: =C10/D10 -> 1.3778076
A11: Rachunek zysków i strat
A12: Przychody netto ze sprzedaży | B12: 307209 | C12: 291027 | D12: 198413 | E12: =B12-C12 -> 16182 | F12: =C12-D12 -> 92614 | G12: =E12/C12 -> 0.055603088 | H12: =F12/D12 -> 0.46677385 | I12: =B12/C12 -> 1.0556031 | J12: =C12/D12 -> 1.4667739
A13: Koszt własny sprzedaży | B13: 255102 | C13: 234233 | D13: 160148 | E13: =B13-C13 -> 20869 | F13: =C13-D13 -> 74085 | G13: =E13/C13 -> 0.089095046 | H13: =F13/D13 -> 0.46260334 | I13: =B13/C13 -> 1.089095 | J13: =C13/D13 -> 1.4626033
A14: Zysk brutto na sprzedaży | B14: 52107 | C14: 56794 | D14: 38265 | E14: =B14-C14 -> -4687 | F14: =C14-D14 -> 18529 | G14: =E14/C14 -> -0.082526323 | H14: =F14/D14 -> 0.48422841 | I14: =B14/C14 -> 0.91747368 | J14: =C14/D14 -> 1.4842284
A15: Zysk/(strata) na działalności operacyjnej | B15: 11882 | C15: 17319 | D15: 1340 | E15: =B15-C15 -> -5437 | F15: =C15-D15 -> 15979 | G15: =E15/C15 -> -0.31393268 | H15: =F15/D15 -> 11.924627 | I15: =B15/C15 -> 0.68606732 | J15: =C15/D15 -> 12.924627
A16: Zysk/(strata) przed opodatkowaniem | B16: 13008 | C16: 16550 | D16: 1096 | E16: =B16-C16 -> -3542 | F16: =C16-D16 -> 15454 | G16: =E16/C16 -> -0.21401813 | H16: =F16/D16 -> 14.100365 | I16: =B16/C16 -> 0.78598187 | J16: =C16/D16 -> 15.100365
A17: Zysk/(strata) netto | B17: 10319 | C17: 13269 | D17: 715 | E17: =B17-C17 -> -2950 | F17: =C17-D17 -> 12554 | G17: =E17/C17 -> -0.22232271 | H17: =F17/D17 -> 17.558042 | I17: =B17/C17 -> 0.77767729 | J17: =C17/D17 -> 18.558042
A18: Cash flow
A19: PP netto z działalności operacyjnej | B19: 54644 | C19: 37177 | D19: 12062 | E19: =B19-C19 -> 17467 | F19: =C19-D19 -> 25115 | G19: =E19/C19 -> 0.4698335 | H19: =F19/D19 -> 2.0821588 | I19: =B19/C19 -> 1.4698335 | J19: =C19/D19 -> 3.0821588
A20: PP netto z działalności inwestycyjnej | B20: -22993 | C20: -21785 | D20: -2921 | E20: =B20-C20 -> -1208 | F20: =C20-D20 -> -18864 | G20: =E20/C20 -> 0.055450998 | H20: =F20/D20 -> 6.4580623 | I20: =B20/C20 -> 1.055451 | J20: =C20/D20 -> 7.4580623
A21: PP netto z działalności finansowej | B21: -9502 | C21: 1256 | D21: -2970 | E21: =B21-C21 -> -10758 | F21: =C21-D21 -> 4226 | G21: =E21/C21 -> -8.5652866 | H21: =F21/D21 -> -1.4228956 | I21: =B21/C21 -> -7.5652866 | J21: =C21/D21 -> -0.42289562
A22: PRZEPŁYWY PIENIĘŻNE NETTO RAZEM | B22: 22149 | C22: 16648 | D22: 6171 | E22: =B22-C22 -> 5501 | F22: =C22-D22 -> 10477 | G22: =E22/C22 -> 0.33043008 | H22: =F22/D22 -> 1.6977799 | I22: =B22/C22 -> 1.3304301 | J22: =C22/D22 -> 2.6977799
A24: 2. Analiza pionowa
A25: Wskaźnik / rok | B25: 2024 | C25: 2023 | D25: 2022 | F25: Wnioski : - Struktura aktywów charakteryzuje się dominacją majątku obrotowego, którego udział wzrósł z 65,03% w 2022 r. do 75,66% w 2024 r. Jest to typowe dla branży IT, gdzie kluczowe są zasoby ludzkie i bieżące kontrakty, a nie ciężka infrastruktura. -Zmiana struktury finansowania - Udział kapitału własnego w pasywach ogółem systematycznie spada (z 48,61% do 37,14%), co wskazuje na coraz większe posiłkowanie się kapitałem obcym. -Udział zysku netto w przychodach spadł w ostatnim roku z 4,56% do 3,36%, co potwierdza presję rosnących kosztów na marże spółki. -Mimo dynamicznego wzrostu przychodów w badanym okresie, udział zysku operacyjnego (EBIT) w przychodach netto uległ znacznemu pogorszeniu, spadając z 5,95% w 2023 r. do zaledwie 3,87% w 2024 r. Wskazuje to na spadek rentowności podstawowej działalności operacyjnej i sugeruje konieczność głębszej analizy kosztów zarządu lub sprzedaży, które rosły szybciej niż wypracowana marża brutto.
A26: Struktura aktywów/ pasywów
A27: Udział aktywów trwałych w aktywach ogółem | B27: =B4/B6 -> 0.24335626 | C27: =C4/C6 -> 0.28501817 | D27: =D4/D6 -> 0.34973027
A28: Udział aktywów obrotowych w aktywach ogółem | B28: =B5/B6 -> 0.75664374 | C28: =C5/C6 -> 0.71498183 | D28: =D5/D6 -> 0.65026973
A29: Udział kapitału wł. w pasywach ogółem | B29: =B7/B10 -> 0.37135878 | C29: =C7/C10 -> 0.41937646 | D29: =D7/D10 -> 0.48613146
A30: Udział kapitałów obcych w pasywach ogółem | B30: =(B8+B9)/B10 -> 0.62864122 | C30: =(C8+C9)/C10 -> 0.58062354 | D30: =(D8+D9)/D10 -> 0.51386854
A31: Struktura kosztów / wyników
A32: Stosunek kosztu wł. do przychodów netto ze sprzedaży | B32: =B13/B$12 -> 0.83038583 | C32: =C13/C12 -> 0.80484972 | D32: =D13/D12 -> 0.80714469
A33: Stosunek zysku brutto do przychodów netto ze sprzedaży | B33: =B14/B$12 -> 0.16961417 | C33: =C14/C$12 -> 0.19515028 | D33: =D14/D$12 -> 0.19285531
A34: Stosunek zysku na działalności op. do przychodów netto ze sprzedaży (EBIT) | B34: =B15/B$12 -> 0.038677252 | C34: =C15/C$12 -> 0.059509942 | D34: =D15/D$12 -> 0.0067535897
A35: Stosunek zysku netto do przychodów netto ze sprzedaży | B35: =B17/B12 -> 0.033589511 | C35: =C17/C12 -> 0.045593708 | D35: =D17/D12 -> 0.0036035945
A37: 3. Analiza pionowo - pozioma | F37: Wnioski: -Złota Reguła Bilansowa: Spółka w całym badanym okresie spełnia Złotą Regułę Bilansową (wskaźnik powyżej 1,0), osiągając w 2024 r. poziom 1,53. Oznacza to, że aktywa trwałe są w całości finansowane najbardziej stabilnym kapitałem własnym. -Srebrna Reguła Bilansowa: Wskaźnik pokrycia aktywów trwałych kapitałem stałym wynosi 1,93 w 2024 r. Tak wysoki poziom zapewnia spółce bardzo duże bezpieczeństwo finansowe i długoterminową stabilność. - Kapitał stały z dużym marginesem finansuje majątek trwały, co pozwala na finansowanie części aktywów obrotowych bezpiecznymi źródłami długoterminowymi.
A38: Reguła | B38: Wzór | C38: 2024 | D38: 2023 | E38: 2022
A39: Złota Reguła Bilansowa | B39: Kapitał wł. / aktywa trwałe | C39: =B7/B4 -> 1.5259882 | D39: =C7/C4 -> 1.4714026 | E39: =D7/D4 -> 1.3900183
A40: Srebrna Reguła Bilansowa | B40: (Kapitał wł. + zob. dł.) / aktywa trwałe | C40: =(B7+B8)/B4 -> 1.9255732 | D40: =(C7+C8)/C4 -> 1.8517707 | E40: =(D7+D8)/D4 -> 1.553899
A45: 4. Wstępna analiza przepływów pieniężnych | F45: Wnioski?
A46: Rok | B46: Dz operacyjna | C46: Dz inwestycyjna | D46: Dz finansowa | E46: Wariant
...

Sheet Analiza wskaźnikowa
A1: Typ wskaźnika | B1: Nazwa wskaźnika | C1: Sposób wyliczenia | D1: Wskaźnik ustalony za:
D2: Spółka 2022 | E2: Sektor 2022 | F2: Spółka 2023 | G2: Sektor 2023 | H2: Spółka 2024
A3: Wskaźniki rentowności | B3: Rentowność operacyjna aktywów | C3: wynik z działalności operacyjnej*100/średnioroczny stan aktywów ogółem | D3: =(RZiS!E8 * 100) /WybraneElementy!D8 -> 0.93035527 | E3: 17.77 | F3: =(RZiS!D8 * 100) / ((Bilans!E20+Bilans!D20)/2) -> 10.113934 | G3: 16.68 | H3: =(RZiS!C8 * 100) / ((Bilans!D20+Bilans!C20)/2) -> 5.5243404
B4: Rentowność kapitału własnego | C4: wynik netto*100/średnioroczny stan kapitału własnego | D4: =RZiS!E13*100 / Bilans!E22 -> 1.021166 | E4: 29.62 | F4: =RZiS!D13*100 / ((Bilans!E22+Bilans!D22)/2) -> 17.317707 | G4: 26.09 | H4: =RZiS!C13*100/((Bilans!C22+Bilans!D22)/2) -> 12.191923
B5: Rentowność sprzedaży netto | C5: wynik netto*100/przychody ogółem | D5: =RZiS!E13*100/(RZiS!E2+Table004__Page_5[[#This Row],[2022 r.]]+RZiS!E9) -> 0.35843372 | E5: 8.46 | F5: =RZiS!D13*100 / (RZiS!D2+Table004__Page_5[[#This Row],[2023 r.]]+RZiS!D9) -> 4.5308957 | G5: 8.1 | H5: =RZiS!C13*100 / (RZiS!C2+Table004__Page_5[[#This Row],[2024 r.]]+RZiS!C9) -> 3.3168226
B6: Rentowność sprzedaży | C6: wynik ze sprzedaży*100/przychody netto ze sprzedaży produktów,towarów i materiałów | D6: =(RZiS!E4*100) / RZiS!E2 -> 19.285531 | E6: 9.26 | F6: =RZiS!D4*100/RZiS!D2 -> 19.515028 | G6: 9.31 | H6: =RZiS!C4*100/RZiS!C2 -> 16.961417
B7: Rentowność ekonomiczna sprzedaży | C7: (wynik z działalności operacyjnej+amortyzajca)*100/wynik ze sprzedaży*100/przychody ze sprzedaży produktów, towarów i materiałów + pozostałe przychody operacyjne | D7: =(RZiS!E8+'Cash Flow'!D6)*100/(RZiS!E2+RZiS!E5) -> 4.0372295 | E7: 11.64 | F7: =(RZiS!D8+'Cash Flow'!C6)*100/(RZiS!D2+RZiS!D5) -> 8.2830964 | G7: 11.65 | H7: =(RZiS!C8+'Cash Flow'!B6)*100/(RZiS!C2+RZiS!C5) -> 5.9539202
A8: Wskaźniki płynności finansowej | B8: Płynność bieżąca(płynność finansowa I stopnia) | C8: aktywa obrotowe ogółem (bez należności z tytułu dostaw i usług o okresie spłaty powyżej 12 mies.) / zobowiązania krótkoterminowe3 (bez zobowiązań z tytułu dostaw i usług o okresie wymagalności powyżej 12 mies.) | D8: =Bilans!E12/Bilans!E33 -> 1.4242982 | E8: 3.86 | F8: =Bilans!D12/Bilans!D33 -> 1.5141128 | G8: 4.06 | H8: =Bilans!C12/Bilans!C33 -> 1.4238693
B9: Płynność szybka ( płynność finansowa II stopnia) | C9: aktywa obrotowe ogółem (bez należności z tytułu dostaw i usług o okresie spłaty powyżej 12 mies.) - zapasy - krótkoterminowe rozliczenia międzyokresowe / zobowiązania krótkoterminowe3 (bez zobowiązań z tytułu dostaw i usług o okresie wymagalności powyżej 12 mies.) | D9: =(Bilans!E12-Bilans!E13)/Bilans!E33 -> 1.2535965 | E9: 3.43 | F9: =(Bilans!D12-Bilans!D13)/Bilans!D33 -> 1.470371 | G9: 3.58 | H9: =(Bilans!C12-Bilans!C13)/Bilans!C33 -> 1.4023892
B10: Płynność gotówkowa (płynność finansowa III stopnia) | C10: inwestycje krótkoterminowe / zobowiązania krótkoterminowe3 (bez zobowiązań z tytułu dostaw i usług o okresie wymagalności powyżej 12 mies.) | D10: =Bilans!E19/Bilans!E33 -> 0.19745126 | E10: 1.66 | F10: =Bilans!D19/Bilans!D33 -> 0.31621296 | G10: 1.77 | H10: =Bilans!C20/Bilans!C33 -> 1.8818227
A11: Wskaźniki sprawności działania (Rotacja) | B11: Rotacja aktywów ogółem | C11: przychody netto ze sprzedaży/ przeciętny stan aktywów ogółem | D11: =WybraneElementy!D19/WybraneElementy!$G$2 -> 1.0366405 | F11: =WybraneElementy!C19/WybraneElementy!G2 -> 1.5205172 | H11: =WybraneElementy!B19/WybraneElementy!G2 -> 1.6050627
B12: Rotacja zapasów (krotność) | C12: przychody netto ze sprzedaży/ średni stan zapasów | D12: =WybraneElementy!D19/WybraneElementy!G3 -> 33.125883 | F12: =WybraneElementy!C19/WybraneElementy!$G$3 -> 48.58818 | H12: =WybraneElementy!B19/WybraneElementy!$G$3 -> 51.289832
B13: Rotacja należności (krotność) | C13: przychody netto ze sprzedaży/ średni stan należności | D13: =WybraneElementy!D19/WybraneElementy!G4 -> 3.8475495 | F13: =WybraneElementy!C19/WybraneElementy!$G$4 -> 5.6434851 | H13: =WybraneElementy!B19/WybraneElementy!$G$4 -> 5.9572803
B14: Okres spływu należności | C14: średnioroczny stan ogółu należności z tytułu dostaw i usług x 365 / przychody ze sprzedaży produktów, towarów i materiałów | D14: =Bilans!E15*365/RZiS!E2 -> 88.135102 | E14: 54.03 | F14: =((Bilans!E15+Bilans!D15)/2 * 365)/RZiS!D2 -> 63.911716 | G14: 55.01 | H14: =((Bilans!D15+Bilans!C15)/2 * 365)/RZiS!C2 -> 63.443031
B15: Okres spłaty zobowiązań | C15: średnioroczny stan ogółu zobowiązań z tytułu dostaw i usług x 365 / przychody ze sprzedaży produktów, towarów i materiałów | D15: =Bilans!E38*365/RZiS!E2 -> 60.474918 | E15: 27.08 | F15: =((Bilans!E38+Bilans!D38)/2 * 365)/RZiS!D2 -> 46.948316 | G15: 27.08 | H15: =((Bilans!D38+Bilans!C38)/2 * 365)/RZiS!C2 -> 70.16658
B16: Szybkość obrotu zapasów | C16: średnioroczny stan zapasów x 365 / przychody ze sprzedaży produktów, towarów i materiałów | D16: =11225*365/RZiS!E2 -> 20.649479 | E16: 24.82 | F16: =(11225+4099)/2 *365/RZiS!D2 -> 9.6095208 | G16: 24.4 | H16: =(4099+2645)/2 * 365/RZiS!C2 -> 4.0063279
A17: Wskaźniki zadłużenia | B17: Pokrycie aktywów trwałych kapitałem własnym i rezerwami długoterminowymi | C17: kapitał (fundusz) własny + rezerwy długoterminowe / aktywa trwałe + należności z tytułu dostaw i usług o okresie spłaty powyżej 12 mies | D17: =(Bilans!E22+Bilans!E32)/Bilans!E2 -> 1.4066545 | E17: 6.12 | F17: =(Bilans!D22+Bilans!D32)/Bilans!D2 -> 1.4857764 | G17: 6.17 | H17: =(Bilans!C22+Bilans!C32)/Bilans!C2 -> 1.5409019
B18: Trwałość struktury finansowania | C18: kapitał (fundusz) własny + rezerwy długoterminowe + zobowiązania długoterminowe (łącznie z zobowiązaniami8 z tytułu dostaw i usług powyżej 12 mies.)/ aktywa ogółem | D18: =(Bilans!E22+Bilans!E32+Bilans!E26)/Bilans!E20 -> 0.5492637 | E18: 0.66 | F18: =(Bilans!D22+Bilans!D32+Bilans!D26)/Bilans!D20 -> 0.53188509 | G18: 0.67 | H18: =(Bilans!C22+Bilans!C32+Bilans!C26)/Bilans!C20 -> 0.47222965
B19: Ogólne zadłużenie | C19: zobowiązania i rezerwy na zobowiązania x 100 / aktywa ogółem | D19: =(Bilans!E26+Bilans!E22)*100/Bilans!E20 -> 54.344551 | E19: 36.93 | F19: =(Bilans!D26+Bilans!D22)*100/Bilans!D20 -> 52.778828 | G19: 35.27 | H19: =(Bilans!C26+Bilans!C22)*100/Bilans!C20 -> 46.860031
B20: Wskaźnik pokrycia odsetek (statyczny) | C20: Zysk przed opodatkowaniem + Odsetki / Odsetki | D20: =(WybraneElementy!D23+WybraneElementy!D42)/WybraneElementy!D42 -> 4.0360111 | F20: =(WybraneElementy!C23+WybraneElementy!C42)/WybraneElementy!C42 -> 53.707006 | H20: =(WybraneElementy!B23+WybraneElementy!B42)/WybraneElementy!B42 -> 13.376784
B21: Zadłużenie kapitału własnego: | C21: Zobowiązania ogółem / kapitał własny | D21: =(Bilans!E26+Bilans!E33)/Bilans!E22 -> 1.0570568 | F21: =(Bilans!D26+Bilans!D33)/Bilans!D22 -> 1.3844925 | H21: =(Bilans!C26+Bilans!C33)/Bilans!C22 -> 1.6928136
A22: Wskaźniki dynamiczne (Cash Flow) | B22: Wydajność gotówkowa sprzedaży | C22: Przepływy pieniężne netto z działalności operacyjnej / Przychody netto ze sprzedaży | D22: ='Cash Flow'!D18/RZiS!E2 -> 0.060792388 | F22: ='Cash Flow'!C18/RZiS!D2 -> 0.12774416 | H22: ='Cash Flow'!B18/RZiS!C2 -> 0.17787239
B23: Wydajność gotówkowa zysku | C23: Przepływy pieniężne netto z działalności operacyjnej​ / Zysk netto | D23: ='Cash Flow'!D18/RZiS!E13 -> 16.86993 | F23: ='Cash Flow'!C18 / RZiS!D13 -> 2.8017937 | H23: ='Cash Flow'!B18/RZiS!C13 -> 5.2954744
B24: Wskaźnik ogólnej wystarczalności gotówki | C24: Przepływy pieniężne netto z działalności operacyjnej / ( Wydatki inwestycyjne + dywidendy + spłąty zobowiązań finansowych) | D24: ='Cash Flow'!D18 / ('Cash Flow'!D25 + 'Cash Flow'!D35) -> 1.0068447 | F24: ='Cash Flow'!C18 / ('Cash Flow'!C25 + 'Cash Flow'!C35) -> 1.378662 | H24: ='Cash Flow'!B18 / ('Cash Flow'!B25 + 'Cash Flow'!B34 +'Cash Flow'!B35) -> 1.3705543
A27: Podsumowanie analizy wskaźnikowej: 1. Rentowność Rok 2022 był wyraźnie słaby, prawie wszystkie wskaźniki rentowności były wyjątkowo niskie, mogło być to spowodowane na przykład wysokimi kosztami bądź niekorzystną sytuacją rynkową. Rentowność sprzedaży na poziomie 19.3% wskazuje jednak, że marża na sprzedaży była opłacalna. Sytuacja zmieniła się w 2023 roku gdzie obserwujemy skok wskaźników, co świadczy o błyskawicznej poprawie efektywności zarządzania i operacji. Przyczyną mogło być: wysokomarżowe rynki, radykalna optymalizacja kosztów (restrukturyzacja) lub zakończenie kosztownych inwestycji, które zaczęły przynosić efekty. Spadek wskaźników w 2024 roku (choć wciąż wysoki) jest naturalnym zjawiskiem po roku rekordowym. Porównanie z sektorem: Mimo poprawy, Atende nadal operuje na marżach niższych niż średnia w branży IT. Wskazuje to na specyfikę modelu Atende (integracja systemów), który jest kapitałochłonny i cechuje się wyższą bazą kosztową niż typowe firmy "czysto" programistyczne. 2. Wskaźniki płynności finansowej W latach 2022 i 2023 płynność bieżąca i szybka utrzymywały się na bezpiecznym, stabilnym poziomie, co gwarantowało zdolność do terminowego regulowania zobowiązań. Nawet w trudnym 2022 roku firma nie traciła kontroli nad kapitałem obrotowym netto. Wskaźnik płynności gotówkowej, który w poprzednich latach wskazywał na umiarkowany poziom gotówki (0.2-0.3), w 2024 roku wzrósł gwałtownie do poziomu 1.88. Oznacza to, że firma zgromadziła bardzo duże wolne środki pieniężne, które niemal dwukrotnie pokrywają jej bieżące zobowiązania. Przyczyna: firma prawdopodobnie odroczyła duże wydatki inwestycyjne, sprzedała nieużywane aktywa, lub świetnie zarządza kapitałem obrotowym. Porównanie z sektorem: Choć Atende ma niższy wskaźnik bieżący niż średnia sektora, jego obecna struktura płynności jest znacznie zdrowsza i mniej ryzykowna - atende efektywniej wykorzystuje kapitał, zachowując przy tym bezpieczną ilość pieniędzy w gotówce. 3. Wskaźniki sprawności działania Wskaźniki rotacji aktywów ogółem, zapasów, należności wzrastają z każdym rokiem, w szczególności między rokiem 2022 a 2023.Jednoczesny wzrost rotacji aktywów, należności i zapasów świadczy o tym, że firma skróciła swój cykl operacyjny. Pozwala to na szybsze uwalnianie gotówki zamrożonej w działalności, co potwierdza gwałtowny wzrost płynności gotówkowej w 2024 roku (do poziomu 1,88). Jest to oznaka zdrowego rozwoju i bardzo wysokiej sprawności logistyczno-finansowej na tle sektora IT. Jednocześnie firma sama znacząco wydłużyła okres spłaty swoich zobowiązań wobec dostawców, co jest skutecznym, choć ryzykownym, źródłem darmowego finansowania kapitału obrotowego. Pozytywnym zjawiskiem jest natomiast radykalne skrócenie okresu magazynowania zapasów , co świadczy o bardzo efektywnej logistyce i zarządzaniu łańcuchem dostaw. Porównanie z sektorem: Atende zarządza zapasami znacznie sprawniej niż branża (24dni - 4 dni). Dodatkowo firma finansuje pieniędzmi dostawców (cykl spłaty 70 dni przy średniej sektorowej 27 dni), co jest strategiczną przewagą w zarządzaniu kapitałem obrotowym. 4. Wskaźniki zadłużenia Wskaźnik ogólnego zadłużenia konsekwentnie spadał z 54.3% w 2022 roku do 46.9% w 2024 roku. Oznacza to, że udział kapitałów obcych w finansowaniu aktywów maleje, a firma staje się mniej zależna od wierzycieli, co zwiększa jej stabilność finansową. Wskaźnik pokrycia aktywów trwałych kapitałami stałymi rośnie z 1,41 do 1,54, co oznacza, że firma w pełni finansuje swój majątek trwały (grunty, maszyny) stabilnymi, długoterminowymi źródłami, takimi jak kapitał własny i rezerwy. Jest to korzystne zjawisko, potwierdzające przestrzeganie tzw. "złotej reguły bankowej". Mimo to, wskaźnik zadłużenia kapitału własnego wzrósł znacząco i maleje długoterminowy udział stabilnych źródeł w finansowaniu ogółem. Porównanie z sektorem: Zadłużenie Atende jest wyższe niż średnia branżowa (35,27%), jednak przy tak wysokim pokryciu odsetek zyskiem (13,38x) nie stanowi to zagrożenia, lecz świadczy o odważnym finansowaniu rozwoju 5.Wskaźniki dynamiczne Przepływy pieniężne firmy systematycznie się wzmacniają. Z działalności operacyjnej generuje ona coraz więcej gotówki w stosunku do osiąganych przychodów, a jednocześnie zysk netto coraz lepiej przekłada się na realny wpływ środków. Firma jest samowystarczalna finansowo. Środki z działalności operacyjnej w pełni pokrywają jej wydatki inwestycyjne, ewentualne dywidendy oraz spłaty zobowiązań, co eliminuje potrzebę zewnętrznego finansowania tych celów i świadczy o dużej sile finansowej.

Sheet Wnioski końcowe

Sheet Komentarz zesp. oc.
A1: Kryterium oceny | B1: Opis | C1: Punkty (1-5) | D1: Komentarz
A2: Wskaźniki | B2: Poprawne formuły i ustalone wartości | C2: 5 | D2: Sprawdzilismy po 2 wskazniki z kazdego typu
A3: Wnioski cząstkowe | B3: Poprawna interpretacja wyników, porównanie branżowe | C3: 5 | D3: Szczegolowa interpretacja kazdej czesci, na kazdym etapie porownanie branzowe
A4: Wizualizacje | B4: Czytelność i jakość merytoryczna wykresów, tabel, rysunków | C4: 5 | D4: Są wykresy, które przedstawiaja czytelnie dane
A5: Wnioski końcowe i rekomendacje | B5: Wskazanie problemu i praktyczne sugestie | C5: 5 | D5: Brak wiekszych problemów spółki
A6: Ocena końcowa | B6: Suma uzyskanych punktów | C6: =SUM(C2:C5) -> 20
